Workbook

Sheet 🎯 Dashboard
B1: 🎯 TABLEAU DE BORD BUDGÉTAIRE | ENCG SETTAT | 2024-2025
B5: Budget vs Réalisé • 5 Départements • 8 Postes de Charges • 12 Mois • Données synthétiques 480 lignes
B7: 💰 BUDGET TOTAL | E7: 📊 RÉALISÉ TOTAL | H7: ⚖️ ÉCART GLOBAL | K7: 📈 TAUX CONSOMMATION
B8: ='📋 Analyse Départements'!C10 | E8: ='📋 Analyse Départements'!D10 | H8: ='📋 Analyse Départements'!E10 | K8: ='📋 Analyse Départements'!F10
B13: ⚠️ NB DÉPASSEMENTS | E13: ✅ NB ÉCONOMIES | H13: 🏢 DÉPARTEMENTS | K13: 📅 MOIS ANALYSÉS
B14: ='📋 Analyse Départements'!H10 | E14: ='📋 Analyse Départements'!I10 | H14: =COUNTA('📋 Analyse Départements'!A5:A9) | K14: =COUNTA('📋 Analyse Départements'!A15:A26)
B19: 📊 BUDGET vs RÉALISÉ PAR DÉPARTEMENT (annuel)
B20: Département | C20: Budget (MAD) | D20: Réalisé (MAD) | E20: Écart (MAD) | F20: Écart % | G20: Taux Conso | H20: Statut
B21: RH | C21: ='📋 Analyse Départements'!B5 | D21: ='📋 Analyse Départements'!C5 | E21: ='📋 Analyse Départements'!D5 | F21: ='📋 Analyse Départements'!E5 | G21: ='📋 Analyse Départements'!F5 | H21: ='📋 Analyse Départements'!I5
B22: Marketing | C22: ='📋 Analyse Départements'!B6 | D22: ='📋 Analyse Départements'!C6 | E22: ='📋 Analyse Départements'!D6 | F22: ='📋 Analyse Départements'!E6 | G22: ='📋 Analyse Départements'!F6 | H22: ='📋 Analyse Départements'!I6
B23: Production | C23: ='📋 Analyse Départements'!B7 | D23: ='📋 Analyse Départements'!C7 | E23: ='📋 Analyse Départements'!D7 | F23: ='📋 Analyse Départements'!E7 | G23: ='📋 Analyse Départements'!F7 | H23: ='📋 Analyse Départements'!I7
B24: IT | C24: ='📋 Analyse Départements'!B8 | D24: ='📋 Analyse Départements'!C8 | E24: ='📋 Analyse Départements'!D8 | F24: ='📋 Analyse Départements'!E8 | G24: ='📋 Analyse Départements'!F8 | H24: ='📋 Analyse Départements'!I8
B25: Administration | C25: ='📋 Analyse Départements'!B9 | D25: ='📋 Analyse Départements'!C9 | E25: ='📋 Analyse Départements'!D9 | F25: ='📋 Analyse Départements'!E9 | G25: ='📋 Analyse Départements'!F9 | H25: ='📋 Analyse Départements'!I9
B26: TOTAL GÉNÉRAL | C26: ='📋 Analyse Départements'!C10 | D26: ='📋 Analyse Départements'!D10 | E26: ='📋 Analyse Départements'!E10 | F26: ='📋 Analyse Départements'!F10 | G26: ='📋 Analyse Départements'!G10
B28: 📅 ÉVOLUTION MENSUELLE — Budget vs Réalisé (tous départements)
B29: Mois | C29: Budget | D29: Réalisé | E29: Écart | F29: Écart % | G29: Statut
B30: Janvier | C30: ='📋 Analyse Départements'!C15 | D30: ='📋 Analyse Départements'!D15 | E30: ='📋 Analyse Départements'!E15 | F30: ='📋 Analyse Départements'!F15 | G30: ='📋 Analyse Départements'!J15
B31: Février | C31: ='📋 Analyse Départements'!C16 | D31: ='📋 Analyse Départements'!D16 | E31: ='📋 Analyse Départements'!E16 | F31: ='📋 Analyse Départements'!F16 | G31: ='📋 Analyse Départements'!J16
B32: Mars | C32: ='📋 Analyse Départements'!C17 | D32: ='📋 Analyse Départements'!D17 | E32: ='📋 Analyse Départements'!E17 | F32: ='📋 Analyse Départements'!F17 | G32: ='📋 Analyse Départements'!J17
B33: Avril | C33: ='📋 Analyse Départements'!C18 | D33: ='📋 Analyse Départements'!D18 | E33: ='📋 Analyse Départements'!E18 | F33: ='📋 Analyse Départements'!F18 | G33: ='📋 Analyse Départements'!J18
B34: Mai | C34: ='📋 Analyse Départements'!C19 | D34: ='📋 Analyse Départements'!D19 | E34: ='📋 Analyse Départements'!E19 | F34: ='📋 Analyse Départements'!F19 | G34: ='📋 Analyse Départements'!J19
B35: Juin | C35: ='📋 Analyse Départements'!C20 | D35: ='📋 Analyse Départements'!D20 | E35: ='📋 Analyse Départements'!E20 | F35: ='📋 Analyse Départements'!F20 | G35: ='📋 Analyse Départements'!J20
B36: Juillet | C36: ='📋 Analyse Départements'!C21 | D36: ='📋 Analyse Départements'!D21 | E36: ='📋 Analyse Départements'!E21 | F36: ='📋 Analyse Départements'!F21 | G36: ='📋 Analyse Départements'!J21
B37: Août | C37: ='📋 Analyse Départements'!C22 | D37: ='📋 Analyse Départements'!D22 | E37: ='📋 Analyse Départements'!E22 | F37: ='📋 Analyse Départements'!F22 | G37: ='📋 Analyse Départements'!J22
B38: Septembre | C38: ='📋 Analyse Départements'!C23 | D38: ='📋 Analyse Départements'!D23 | E38: ='📋 Analyse Départements'!E23 | F38: ='📋 Analyse Départements'!F23 | G38: ='📋 Analyse Départements'!J23
B39: Octobre | C39: ='📋 Analyse Départements'!C24 | D39: ='📋 Analyse Départements'!D24 | E39: ='📋 Analyse Départements'!E24 | F39: ='📋 Analyse Départements'!F24 | G39: ='📋 Analyse Départements'!J24
B40: Novembre | C40: ='📋 Analyse Départements'!C25 | D40: ='📋 Analyse Départements'!D25 | E40: ='📋 Analyse Départements'!E25 | F40: ='📋 Analyse Départements'!F25 | G40: ='📋 Analyse Départements'!J25
B41: Décembre | C41: ='📋 Analyse Départements'!C26 | D41: ='📋 Analyse Départements'!D26 | E41: ='📋 Analyse Départements'!E26 | F41: ='📋 Analyse Départements'!F26 | G41: ='📋 Analyse Départements'!J26
B42: TOTAL ANNUEL | C42: ='📋 Analyse Départements'!C27 | D42: ='📋 Analyse Départements'!D27 | E42: ='📋 Analyse Départements'!E27 | F42: ='📋 Analyse Départements'!F27
B44: 📋 SYNTHÈSE PAR POSTE DE CHARGES — Taux de dépassement
B45: Poste de Charges | C45: Budget | D45: Réalisé | E45: Écart % | F45: Taux Conso | G45: Statut
B46: Salaires | C46: ='📈 Analyse Postes & Alertes'!B5 | D46: ='📈 Analyse Postes & Alertes'!C5 | E46: ='📈 Analyse Postes & Alertes'!E5 | F46: ='📈 Analyse Postes & Alertes'!G5 | G46: ='📈 Analyse Postes & Alertes'!J5
B47: Charges sociales | C47: ='📈 Analyse Postes & Alertes'!B6 | D47: ='📈 Analyse Postes & Alertes'!C6 | E47: ='📈 Analyse Postes & Alertes'!E6 | F47: ='📈 Analyse Postes & Alertes'!G6 | G47: ='📈 Analyse Postes & Alertes'!J6
B48: Loyer & Charges | C48: ='📈 Analyse Postes & Alertes'!B7 | D48: ='📈 Analyse Postes & Alertes'!C7 | E48: ='📈 Analyse Postes & Alertes'!E7 | F48: ='📈 Analyse Postes & Alertes'!G7 | G48: ='📈 Analyse Postes & Alertes'!J7
B49: Matières & Fournitures | C49: ='📈 Analyse Postes & Alertes'!B8 | D49: ='📈 Analyse Postes & Alertes'!C8 | E49: ='📈 Analyse Postes & Alertes'!E8 | F49: ='📈 Analyse Postes & Alertes'!G8 | G49: ='📈 Analyse Postes & Alertes'!J8
B50: Informatique & Licences | C50: ='📈 Analyse Postes & Alertes'!B9 | D50: ='📈 Analyse Postes & Alertes'!C9 | E50: ='📈 Analyse Postes & Alertes'!E9 | F50: ='📈 Analyse Postes & Alertes'!G9 | G50: ='📈 Analyse Postes & Alertes'!J9
B51: Déplacements & Missions | C51: ='📈 Analyse Postes & Alertes'!B10 | D51: ='📈 Analyse Postes & Alertes'!C10 | E51: ='📈 Analyse Postes & Alertes'!E10 | F51: ='📈 Analyse Postes & Alertes'!G10 | G51: ='📈 Analyse Postes & Alertes'!J10
B52: Formation | C52: ='📈 Analyse Postes & Alertes'!B11 | D52: ='📈 Analyse Postes & Alertes'!C11 | E52: ='📈 Analyse Postes & Alertes'!E11 | F52: ='📈 Analyse Postes & Alertes'!G11 | G52: ='📈 Analyse Postes & Alertes'!J11
B53: Publicité & Communication | C53: ='📈 Analyse Postes & Alertes'!B12 | D53: ='📈 Analyse Postes & Alertes'!C12 | E53: ='📈 Analyse Postes & Alertes'!E12 | F53: ='📈 Analyse Postes & Alertes'!G12 | G53: ='📈 Analyse Postes & Alertes'!J12
B54: TOTAL | C54: ='📈 Analyse Postes & Alertes'!B13 | D54: ='📈 Analyse Postes & Alertes'!C13 | E54: ='📈 Analyse Postes & Alertes'!E13
...

Sheet 📊 Données Brutes
A1: DONNÉES BUDGÉTAIRES — ENCG SETTAT | 2024-2025 | Budget vs Réalisé par Département & Poste de Charges
A2: Mois | B2: N° Mois | C2: Département | D2: Poste de Charges | E2: Budget (MAD) | F2: Réalisé (MAD) | G2: Écart (MAD) | H2: Écart (%) | I2: Statut | J2: Cumulé Budget | K2: Cumulé Réalisé | L2: Taux Consommation
A3: Janvier | B3: 1 | C3: RH | D3: Salaires | E3: 180000 | F3: 193639 | G3: =F3-E3 | H3: =IF(E3=0,0,(F3-E3)/E3) | I3: =IF(H3>0.1,"⚠️ Dépassement",IF(H3<-0.1,"✅ Économie","🔵 Normal")) | J3: =SUMPRODUCT((B$3:B3=B3)*(C$3:C3=C3)*(D$3:D3=D3)*E$3:E3) | K3: =SUMPRODUCT((B$3:B3=B3)*(C$3:C3=C3)*(D$3:D3=D3)*F$3:F3) | L3: =IF(J3=0,0,K3/J3)
A4: Janvier | B4: 1 | C4: RH | D4: Charges sociales | E4: 54000 | F4: 44820 | G4: =F4-E4 | H4: =IF(E4=0,0,(F4-E4)/E4) | I4: =IF(H4>0.1,"⚠️ Dépassement",IF(H4<-0.1,"✅ Économie","🔵 Normal")) | J4: =SUMPRODUCT((B$3:B4=B4)*(C$3:C4=C4)*(D$3:D4=D4)*E$3:E4) | K4: =SUMPRODUCT((B$3:B4=B4)*(C$3:C4=C4)*(D$3:D4=D4)*F$3:F4) | L4: =IF(J4=0,0,K4/J4)
A5: Janvier | B5: 1 | C5: RH | D5: Loyer & Charges | E5: 15000 | F5: 13950 | G5: =F5-E5 | H5: =IF(E5=0,0,(F5-E5)/E5) | I5: =IF(H5>0.1,"⚠️ Dépassement",IF(H5<-0.1,"✅ Économie","🔵 Normal")) | J5: =SUMPRODUCT((B$3:B5=B5)*(C$3:C5=C5)*(D$3:D5=D5)*E$3:E5) | K5: =SUMPRODUCT((B$3:B5=B5)*(C$3:C5=C5)*(D$3:D5=D5)*F$3:F5) | L5: =IF(J5=0,0,K5/J5)
A6: Janvier | B6: 1 | C6: RH | D6: Matières & Fournitures | E6: 8000 | F6: 7274 | G6: =F6-E6 | H6: =IF(E6=0,0,(F6-E6)/E6) | I6: =IF(H6>0.1,"⚠️ Dépassement",IF(H6<-0.1,"✅ Économie","🔵 Normal")) | J6: =SUMPRODUCT((B$3:B6=B6)*(C$3:C6=C6)*(D$3:D6=D6)*E$3:E6) | K6: =SUMPRODUCT((B$3:B6=B6)*(C$3:C6=C6)*(D$3:D6=D6)*F$3:F6) | L6: =IF(J6=0,0,K6/J6)
A7: Janvier | B7: 1 | C7: RH | D7: Informatique & Licences | E7: 5000 | F7: 5573 | G7: =F7-E7 | H7: =IF(E7=0,0,(F7-E7)/E7) | I7: =IF(H7>0.1,"⚠️ Dépassement",IF(H7<-0.1,"✅ Économie","🔵 Normal")) | J7: =SUMPRODUCT((B$3:B7=B7)*(C$3:C7=C7)*(D$3:D7=D7)*E$3:E7) | K7: =SUMPRODUCT((B$3:B7=B7)*(C$3:C7=C7)*(D$3:D7=D7)*F$3:F7) | L7: =IF(J7=0,0,K7/J7)
A8: Janvier | B8: 1 | C8: RH | D8: Déplacements & Missions | E8: 7000 | F8: 7635 | G8: =F8-E8 | H8: =IF(E8=0,0,(F8-E8)/E8) | I8: =IF(H8>0.1,"⚠️ Dépassement",IF(H8<-0.1,"✅ Économie","🔵 Normal")) | J8: =SUMPRODUCT((B$3:B8=B8)*(C$3:C8=C8)*(D$3:D8=D8)*E$3:E8) | K8: =SUMPRODUCT((B$3:B8=B8)*(C$3:C8=C8)*(D$3:D8=D8)*F$3:F8) | L8: =IF(J8=0,0,K8/J8)
A9: Janvier | B9: 1 | C9: RH | D9: Formation | E9: 20000 | F9: 23537 | G9: =F9-E9 | H9: =IF(E9=0,0,(F9-E9)/E9) | I9: =IF(H9>0.1,"⚠️ Dépassement",IF(H9<-0.1,"✅ Économie","🔵 Normal")) | J9: =SUMPRODUCT((B$3:B9=B9)*(C$3:C9=C9)*(D$3:D9=D9)*E$3:E9) | K9: =SUMPRODUCT((B$3:B9=B9)*(C$3:C9=C9)*(D$3:D9=D9)*F$3:F9) | L9: =IF(J9=0,0,K9/J9)
A10: Janvier | B10: 1 | C10: RH | D10: Publicité & Communication | E10: 3000 | F10: 3640 | G10: =F10-E10 | H10: =IF(E10=0,0,(F10-E10)/E10) | I10: =IF(H10>0.1,"⚠️ Dépassement",IF(H10<-0.1,"✅ Économie","🔵 Normal")) | J10: =SUMPRODUCT((B$3:B10=B10)*(C$3:C10=C10)*(D$3:D10=D10)*E$3:E10) | K10: =SUMPRODUCT((B$3:B10=B10)*(C$3:C10=C10)*(D$3:D10=D10)*F$3:F10) | L10: =IF(J10=0,0,K10/J10)
A11: Janvier | B11: 1 | C11: Marketing | D11: Salaires | E11: 95000 | F11: 79032 | G11: =F11-E11 | H11: =IF(E11=0,0,(F11-E11)/E11) | I11: =IF(H11>0.1,"⚠️ Dépassement",IF(H11<-0.1,"✅ Économie","🔵 Normal")) | J11: =SUMPRODUCT((B$3:B11=B11)*(C$3:C11=C11)*(D$3:D11=D11)*E$3:E11) | K11: =SUMPRODUCT((B$3:B11=B11)*(C$3:C11=C11)*(D$3:D11=D11)*F$3:F11) | L11: =IF(J11=0,0,K11/J11)
A12: Janvier | B12: 1 | C12: Marketing | D12: Charges sociales | E12: 28500 | F12: 25862 | G12: =F12-E12 | H12: =IF(E12=0,0,(F12-E12)/E12) | I12: =IF(H12>0.1,"⚠️ Dépassement",IF(H12<-0.1,"✅ Économie","🔵 Normal")) | J12: =SUMPRODUCT((B$3:B12=B12)*(C$3:C12=C12)*(D$3:D12=D12)*E$3:E12) | K12: =SUMPRODUCT((B$3:B12=B12)*(C$3:C12=C12)*(D$3:D12=D12)*F$3:F12) | L12: =IF(J12=0,0,K12/J12)
A13: Janvier | B13: 1 | C13: Marketing | D13: Loyer & Charges | E13: 12000 | F13: 12266 | G13: =F13-E13 | H13: =IF(E13=0,0,(F13-E13)/E13) | I13: =IF(H13>0.1,"⚠️ Dépassement",IF(H13<-0.1,"✅ Économie","🔵 Normal")) | J13: =SUMPRODUCT((B$3:B13=B13)*(C$3:C13=C13)*(D$3:D13=D13)*E$3:E13) | K13: =SUMPRODUCT((B$3:B13=B13)*(C$3:C13=C13)*(D$3:D13=D13)*F$3:F13) | L13: =IF(J13=0,0,K13/J13)
A14: Janvier | B14: 1 | C14: Marketing | D14: Matières & Fournitures | E14: 6000 | F14: 4984 | G14: =F14-E14 | H14: =IF(E14=0,0,(F14-E14)/E14) | I14: =IF(H14>0.1,"⚠️ Dépassement",IF(H14<-0.1,"✅ Économie","🔵 Normal")) | J14: =SUMPRODUCT((B$3:B14=B14)*(C$3:C14=C14)*(D$3:D14=D14)*E$3:E14) | K14: =SUMPRODUCT((B$3:B14=B14)*(C$3:C14=C14)*(D$3:D14=D14)*F$3:F14) | L14: =IF(J14=0,0,K14/J14)
... A482: Décembre | B482: 12 | C482: Administration | D482: Publicité & Communication | E482: 2000 | F482: 1662 | G482: =F482-E482 | H482: =IF(E482=0,0,(F482-E482)/E482) | I482: =IF(H482>0.1,"⚠️ Dépassement",IF(H482<-0.1,"✅ Économie","🔵 Normal")) | J482: =SUMPRODUCT((B$3:B482=B482)*(C$3:C482=C482)*(D$3:D482=D482)*E$3:E482) | K482: =SUMPRODUCT((B$3:B482=B482)*(C$3:C482=C482)*(D$3:D482=D482)*F$3:F482) | L482: =IF(J482=0,0,K482/J482)

Sheet 📋 Analyse Départements
A1: ANALYSE BUDGÉTAIRE PAR DÉPARTEMENT — Budget vs Réalisé | ENCG SETTAT 2024-2025
A3: ▌ SYNTHÈSE ANNUELLE PAR DÉPARTEMENT
A4: Département | B4: Budget Total (MAD) | C4: Réalisé Total (MAD) | D4: Écart (MAD) | E4: Écart (%) | F4: Taux Consommation | G4: Nb Dépassements | H4: Nb Économies | I4: Statut Global | J4: Prévision Fin Année (MAD)
A5: RH | B5: =SUMIF('📊 Données Brutes'!C:C,A5,'📊 Données Brutes'!E:E) | C5: =SUMIF('📊 Données Brutes'!C:C,A5,'📊 Données Brutes'!F:F) | D5: =C5-B5 | E5: =IF(B5=0,0,(C5-B5)/B5) | F5: =IF(B5=0,0,C5/B5) | G5: =COUNTIFS('📊 Données Brutes'!C:C,A5,'📊 Données Brutes'!I:I,"⚠️ Dépassement") | H5: =COUNTIFS('📊 Données Brutes'!C:C,A5,'📊 Données Brutes'!I:I,"✅ Économie") | I5: =IF(E5>0.1,"🔴 Dépassement",IF(E5<-0.1,"🟢 Sous budget","🟡 Normal")) | J5: =C5/COUNTIF('📊 Données Brutes'!C:C,A5)*96
A6: Marketing | B6: =SUMIF('📊 Données Brutes'!C:C,A6,'📊 Données Brutes'!E:E) | C6: =SUMIF('📊 Données Brutes'!C:C,A6,'📊 Données Brutes'!F:F) | D6: =C6-B6 | E6: =IF(B6=0,0,(C6-B6)/B6) | F6: =IF(B6=0,0,C6/B6) | G6: =COUNTIFS('📊 Données Brutes'!C:C,A6,'📊 Données Brutes'!I:I,"⚠️ Dépassement") | H6: =COUNTIFS('📊 Données Brutes'!C:C,A6,'📊 Données Brutes'!I:I,"✅ Économie") | I6: =IF(E6>0.1,"🔴 Dépassement",IF(E6<-0.1,"🟢 Sous budget","🟡 Normal")) | J6: =C6/COUNTIF('📊 Données Brutes'!C:C,A6)*96
A7: Production | B7: =SUMIF('📊 Données Brutes'!C:C,A7,'📊 Données Brutes'!E:E) | C7: =SUMIF('📊 Données Brutes'!C:C,A7,'📊 Données Brutes'!F:F) | D7: =C7-B7 | E7: =IF(B7=0,0,(C7-B7)/B7) | F7: =IF(B7=0,0,C7/B7) | G7: =COUNTIFS('📊 Données Brutes'!C:C,A7,'📊 Données Brutes'!I:I,"⚠️ Dépassement") | H7: =COUNTIFS('📊 Données Brutes'!C:C,A7,'📊 Données Brutes'!I:I,"✅ Économie") | I7: =IF(E7>0.1,"🔴 Dépassement",IF(E7<-0.1,"🟢 Sous budget","🟡 Normal")) | J7: =C7/COUNTIF('📊 Données Brutes'!C:C,A7)*96
A8: IT | B8: =SUMIF('📊 Données Brutes'!C:C,A8,'📊 Données Brutes'!E:E) | C8: =SUMIF('📊 Données Brutes'!C:C,A8,'📊 Données Brutes'!F:F) | D8: =C8-B8 | E8: =IF(B8=0,0,(C8-B8)/B8) | F8: =IF(B8=0,0,C8/B8) | G8: =COUNTIFS('📊 Données Brutes'!C:C,A8,'📊 Données Brutes'!I:I,"⚠️ Dépassement") | H8: =COUNTIFS('📊 Données Brutes'!C:C,A8,'📊 Données Brutes'!I:I,"✅ Économie") | I8: =IF(E8>0.1,"🔴 Dépassement",IF(E8<-0.1,"🟢 Sous budget","🟡 Normal")) | J8: =C8/COUNTIF('📊 Données Brutes'!C:C,A8)*96
A9: Administration | B9: =SUMIF('📊 Données Brutes'!C:C,A9,'📊 Données Brutes'!E:E) | C9: =SUMIF('📊 Données Brutes'!C:C,A9,'📊 Données Brutes'!F:F) | D9: =C9-B9 | E9: =IF(B9=0,0,(C9-B9)/B9) | F9: =IF(B9=0,0,C9/B9) | G9: =COUNTIFS('📊 Données Brutes'!C:C,A9,'📊 Données Brutes'!I:I,"⚠️ Dépassement") | H9: =COUNTIFS('📊 Données Brutes'!C:C,A9,'📊 Données Brutes'!I:I,"✅ Économie") | I9: =IF(E9>0.1,"🔴 Dépassement",IF(E9<-0.1,"🟢 Sous budget","🟡 Normal")) | J9: =C9/COUNTIF('📊 Données Brutes'!C:C,A9)*96
A10: TOTAL GÉNÉRAL | B10: =SUM(B5:B9) | C10: =SUM(C5:C9) | D10: =SUM(D5:D9) | E10: =IF(B10=0,0,(C10-B10)/B10) | F10: =IF(B10=0,0,C10/B10) | G10: =SUM(G5:G9) | H10: =SUM(H5:H9) | J10: =SUM(J5:J9)
A13: ▌ SYNTHÈSE MENSUELLE — TOUS DÉPARTEMENTS CONFONDUS
A14: Mois | B14: N° Mois | C14: Budget (MAD) | D14: Réalisé (MAD) | E14: Écart (MAD) | F14: Écart (%) | G14: Taux Consommation | H14: Cumulé Budget | I14: Cumulé Réalisé | J14: Statut
A15: Janvier | B15: 1 | C15: =SUMIF('📊 Données Brutes'!B:B,1,'📊 Données Brutes'!E:E) | D15: =SUMIF('📊 Données Brutes'!B:B,1,'📊 Données Brutes'!F:F) | E15: =D15-C15 | F15: =IF(C15=0,0,(D15-C15)/C15) | G15: =IF(C15=0,0,D15/C15) | H15: =SUM(C15:C15) | I15: =SUM(D15:D15) | J15: =IF(F15>0.1,"⚠️ Dépassement",IF(F15<-0.1,"✅ Économie","🔵 Normal"))
A16: Février | B16: 2 | C16: =SUMIF('📊 Données Brutes'!B:B,2,'📊 Données Brutes'!E:E) | D16: =SUMIF('📊 Données Brutes'!B:B,2,'📊 Données Brutes'!F:F) | E16: =D16-C16 | F16: =IF(C16=0,0,(D16-C16)/C16) | G16: =IF(C16=0,0,D16/C16) | H16: =SUM(C15:C16) | I16: =SUM(D15:D16) | J16: =IF(F16>0.1,"⚠️ Dépassement",IF(F16<-0.1,"✅ Économie","🔵 Normal"))
A17: Mars | B17: 3 | C17: =SUMIF('📊 Données Brutes'!B:B,3,'📊 Données Brutes'!E:E) | D17: =SUMIF('📊 Données Brutes'!B:B,3,'📊 Données Brutes'!F:F) | E17: =D17-C17 | F17: =IF(C17=0,0,(D17-C17)/C17) | G17: =IF(C17=0,0,D17/C17) | H17: =SUM(C15:C17) | I17: =SUM(D15:D17) | J17: =IF(F17>0.1,"⚠️ Dépassement",IF(F17<-0.1,"✅ Économie","🔵 Normal"))
A18: Avril | B18: 4 | C18: =SUMIF('📊 Données Brutes'!B:B,4,'📊 Données Brutes'!E:E) | D18: =SUMIF('📊 Données Brutes'!B:B,4,'📊 Données Brutes'!F:F) | E18: =D18-C18 | F18: =IF(C18=0,0,(D18-C18)/C18) | G18: =IF(C18=0,0,D18/C18) | H18: =SUM(C15:C18) | I18: =SUM(D15:D18) | J18: =IF(F18>0.1,"⚠️ Dépassement",IF(F18<-0.1,"✅ Économie","🔵 Normal"))
A19: Mai | B19: 5 | C19: =SUMIF('📊 Données Brutes'!B:B,5,'📊 Données Brutes'!E:E) | D19: =SUMIF('📊 Données Brutes'!B:B,5,'📊 Données Brutes'!F:F) | E19: =D19-C19 | F19: =IF(C19=0,0,(D19-C19)/C19) | G19: =IF(C19=0,0,D19/C19) | H19: =SUM(C15:C19) | I19: =SUM(D15:D19) | J19: =IF(F19>0.1,"⚠️ Dépassement",IF(F19<-0.1,"✅ Économie","🔵 Normal"))
A20: Juin | B20: 6 | C20: =SUMIF('📊 Données Brutes'!B:B,6,'📊 Données Brutes'!E:E) | D20: =SUMIF('📊 Données Brutes'!B:B,6,'📊 Données Brutes'!F:F) | E20: =D20-C20 | F20: =IF(C20=0,0,(D20-C20)/C20) | G20: =IF(C20=0,0,D20/C20) | H20: =SUM(C15:C20) | I20: =SUM(D15:D20) | J20: =IF(F20>0.1,"⚠️ Dépassement",IF(F20<-0.1,"✅ Économie","🔵 Normal"))
A21: Juillet | B21: 7 | C21: =SUMIF('📊 Données Brutes'!B:B,7,'📊 Données Brutes'!E:E) | D21: =SUMIF('📊 Données Brutes'!B:B,7,'📊 Données Brutes'!F:F) | E21: =D21-C21 | F21: =IF(C21=0,0,(D21-C21)/C21) | G21: =IF(C21=0,0,D21/C21) | H21: =SUM(C15:C21) | I21: =SUM(D15:D21) | J21: =IF(F21>0.1,"⚠️ Dépassement",IF(F21<-0.1,"✅ Économie","🔵 Normal"))
A22: Août | B22: 8 | C22: =SUMIF('📊 Données Brutes'!B:B,8,'📊 Données Brutes'!E:E) | D22: =SUMIF('📊 Données Brutes'!B:B,8,'📊 Données Brutes'!F:F) | E22: =D22-C22 | F22: =IF(C22=0,0,(D22-C22)/C22) | G22: =IF(C22=0,0,D22/C22) | H22: =SUM(C15:C22) | I22: =SUM(D15:D22) | J22: =IF(F22>0.1,"⚠️ Dépassement",IF(F22<-0.1,"✅ Économie","🔵 Normal"))
A23: Septembre | B23: 9 | C23: =SUMIF('📊 Données Brutes'!B:B,9,'📊 Données Brutes'!E:E) | D23: =SUMIF('📊 Données Brutes'!B:B,9,'📊 Données Brutes'!F:F) | E23: =D23-C23 | F23: =IF(C23=0,0,(D23-C23)/C23) | G23: =IF(C23=0,0,D23/C23) | H23: =SUM(C15:C23) | I23: =SUM(D15:D23) | J23: =IF(F23>0.1,"⚠️ Dépassement",IF(F23<-0.1,"✅ Économie","🔵 Normal"))
A24: Octobre | B24: 10 | C24: =SUMIF('📊 Données Brutes'!B:B,10,'📊 Données Brutes'!E:E) | D24: =SUMIF('📊 Données Brutes'!B:B,10,'📊 Données Brutes'!F:F) | E24: =D24-C24 | F24: =IF(C24=0,0,(D24-C24)/C24) | G24: =IF(C24=0,0,D24/C24) | H24: =SUM(C15:C24) | I24: =SUM(D15:D24) | J24: =IF(F24>0.1,"⚠️ Dépassement",IF(F24<-0.1,"✅ Économie","🔵 Normal"))
A25: Novembre | B25: 11 | C25: =SUMIF('📊 Données Brutes'!B:B,11,'📊 Données Brutes'!E:E) | D25: =SUMIF('📊 Données Brutes'!B:B,11,'📊 Données Brutes'!F:F) | E25: =D25-C25 | F25: =IF(C25=0,0,(D25-C25)/C25) | G25: =IF(C25=0,0,D25/C25) | H25: =SUM(C15:C25) | I25: =SUM(D15:D25) | J25: =IF(F25>0.1,"⚠️ Dépassement",IF(F25<-0.1,"✅ Économie","🔵 Normal"))
A26: Décembre | B26: 12 | C26: =SUMIF('📊 Données Brutes'!B:B,12,'📊 Données Brutes'!E:E) | D26: =SUMIF('📊 Données Brutes'!B:B,12,'📊 Données Brutes'!F:F) | E26: =D26-C26 | F26: =IF(C26=0,0,(D26-C26)/C26) | G26: =IF(C26=0,0,D26/C26) | H26: =SUM(C15:C26) | I26: =SUM(D15:D26) | J26: =IF(F26>0.1,"⚠️ Dépassement",IF(F26<-0.1,"✅ Économie","🔵 Normal"))
A27: TOTAL | C27: =SUM(C15:C26) | D27: =SUM(D15:D26) | E27: =SUM(E15:E26) | F27: =IF(C27=0,0,(D27-C27)/C27) | G27: =IF(C27=0,0,D27/C27)

Sheet 📈 Analyse Postes & Alertes
A1: ANALYSE PAR POSTE DE CHARGES & ALERTES DE DÉPASSEMENT — ENCG SETTAT 2024-2025
A3: ▌ ANALYSE ANNUELLE PAR POSTE DE CHARGES — Tous départements confondus
A4: Poste de Charges | B4: Budget Total | C4: Réalisé Total | D4: Écart (MAD) | E4: Écart (%) | F4: % Budget Total | G4: Taux Conso | H4: Nb Lignes | I4: Dépassements | J4: Statut | K4: Action
A5: Salaires | B5: =SUMIF('📊 Données Brutes'!D:D,A5,'📊 Données Brutes'!E:E) | C5: =SUMIF('📊 Données Brutes'!D:D,A5,'📊 Données Brutes'!F:F) | D5: =C5-B5 | E5: =IF(B5=0,0,(C5-B5)/B5) | F5: =IF(SUM(B$5:B$12)=0,0,B5/SUM(B$5:B$12)) | G5: =IF(B5=0,0,C5/B5) | H5: =COUNTIF('📊 Données Brutes'!D:D,A5) | I5: =COUNTIFS('📊 Données Brutes'!D:D,A5,'📊 Données Brutes'!I:I,"⚠️ Dépassement") | J5: =IF(E5>0.1,"🔴 CRITIQUE",IF(E5>0.05,"🟠 Attention",IF(E5<-0.1,"🟢 Économie","🔵 OK"))) | K5: =IF(E5>0.1,"⚡ Action requise","—")
A6: Charges sociales | B6: =SUMIF('📊 Données Brutes'!D:D,A6,'📊 Données Brutes'!E:E) | C6: =SUMIF('📊 Données Brutes'!D:D,A6,'📊 Données Brutes'!F:F) | D6: =C6-B6 | E6: =IF(B6=0,0,(C6-B6)/B6) | F6: =IF(SUM(B$5:B$12)=0,0,B6/SUM(B$5:B$12)) | G6: =IF(B6=0,0,C6/B6) | H6: =COUNTIF('📊 Données Brutes'!D:D,A6) | I6: =COUNTIFS('📊 Données Brutes'!D:D,A6,'📊 Données Brutes'!I:I,"⚠️ Dépassement") | J6: =IF(E6>0.1,"🔴 CRITIQUE",IF(E6>0.05,"🟠 Attention",IF(E6<-0.1,"🟢 Économie","🔵 OK"))) | K6: =IF(E6>0.1,"⚡ Action requise","—")
A7: Loyer & Charges | B7: =SUMIF('📊 Données Brutes'!D:D,A7,'📊 Données Brutes'!E:E) | C7: =SUMIF('📊 Données Brutes'!D:D,A7,'📊 Données Brutes'!F:F) | D7: =C7-B7 | E7: =IF(B7=0,0,(C7-B7)/B7) | F7: =IF(SUM(B$5:B$12)=0,0,B7/SUM(B$5:B$12)) | G7: =IF(B7=0,0,C7/B7) | H7: =COUNTIF('📊 Données Brutes'!D:D,A7) | I7: =COUNTIFS('📊 Données Brutes'!D:D,A7,'📊 Données Brutes'!I:I,"⚠️ Dépassement") | J7: =IF(E7>0.1,"🔴 CRITIQUE",IF(E7>0.05,"🟠 Attention",IF(E7<-0.1,"🟢 Économie","🔵 OK"))) | K7: =IF(E7>0.1,"⚡ Action requise","—")
A8: Matières & Fournitures | B8: =SUMIF('📊 Données Brutes'!D:D,A8,'📊 Données Brutes'!E:E) | C8: =SUMIF('📊 Données Brutes'!D:D,A8,'📊 Données Brutes'!F:F) | D8: =C8-B8 | E8: =IF(B8=0,0,(C8-B8)/B8) | F8: =IF(SUM(B$5:B$12)=0,0,B8/SUM(B$5:B$12)) | G8: =IF(B8=0,0,C8/B8) | H8: =COUNTIF('📊 Données Brutes'!D:D,A8) | I8: =COUNTIFS('📊 Données Brutes'!D:D,A8,'📊 Données Brutes'!I:I,"⚠️ Dépassement") | J8: =IF(E8>0.1,"🔴 CRITIQUE",IF(E8>0.05,"🟠 Attention",IF(E8<-0.1,"🟢 Économie","🔵 OK"))) | K8: =IF(E8>0.1,"⚡ Action requise","—")
A9: Informatique & Licences | B9: =SUMIF('📊 Données Brutes'!D:D,A9,'📊 Données Brutes'!E:E) | C9: =SUMIF('📊 Données Brutes'!D:D,A9,'📊 Données Brutes'!F:F) | D9: =C9-B9 | E9: =IF(B9=0,0,(C9-B9)/B9) | F9: =IF(SUM(B$5:B$12)=0,0,B9/SUM(B$5:B$12)) | G9: =IF(B9=0,0,C9/B9) | H9: =COUNTIF('📊 Données Brutes'!D:D,A9) | I9: =COUNTIFS('📊 Données Brutes'!D:D,A9,'📊 Données Brutes'!I:I,"⚠️ Dépassement") | J9: =IF(E9>0.1,"🔴 CRITIQUE",IF(E9>0.05,"🟠 Attention",IF(E9<-0.1,"🟢 Économie","🔵 OK"))) | K9: =IF(E9>0.1,"⚡ Action requise","—")
A10: Déplacements & Missions | B10: =SUMIF('📊 Données Brutes'!D:D,A10,'📊 Données Brutes'!E:E) | C10: =SUMIF('📊 Données Brutes'!D:D,A10,'📊 Données Brutes'!F:F) | D10: =C10-B10 | E10: =IF(B10=0,0,(C10-B10)/B10) | F10: =IF(SUM(B$5:B$12)=0,0,B10/SUM(B$5:B$12)) | G10: =IF(B10=0,0,C10/B10) | H10: =COUNTIF('📊 Données Brutes'!D:D,A10) | I10: =COUNTIFS('📊 Données Brutes'!D:D,A10,'📊 Données Brutes'!I:I,"⚠️ Dépassement") | J10: =IF(E10>0.1,"🔴 CRITIQUE",IF(E10>0.05,"🟠 Attention",IF(E10<-0.1,"🟢 Économie","🔵 OK"))) | K10: =IF(E10>0.1,"⚡ Action requise","—")
A11: Formation | B11: =SUMIF('📊 Données Brutes'!D:D,A11,'📊 Données Brutes'!E:E) | C11: =SUMIF('📊 Données Brutes'!D:D,A11,'📊 Données Brutes'!F:F) | D11: =C11-B11 | E11: =IF(B11=0,0,(C11-B11)/B11) | F11: =IF(SUM(B$5:B$12)=0,0,B11/SUM(B$5:B$12)) | G11: =IF(B11=0,0,C11/B11) | H11: =COUNTIF('📊 Données Brutes'!D:D,A11) | I11: =COUNTIFS('📊 Données Brutes'!D:D,A11,'📊 Données Brutes'!I:I,"⚠️ Dépassement") | J11: =IF(E11>0.1,"🔴 CRITIQUE",IF(E11>0.05,"🟠 Attention",IF(E11<-0.1,"🟢 Économie","🔵 OK"))) | K11: =IF(E11>0.1,"⚡ Action requise","—")
A12: Publicité & Communication | B12: =SUMIF('📊 Données Brutes'!D:D,A12,'📊 Données Brutes'!E:E) | C12: =SUMIF('📊 Données Brutes'!D:D,A12,'📊 Données Brutes'!F:F) | D12: =C12-B12 | E12: =IF(B12=0,0,(C12-B12)/B12) | F12: =IF(SUM(B$5:B$12)=0,0,B12/SUM(B$5:B$12)) | G12: =IF(B12=0,0,C12/B12) | H12: =COUNTIF('📊 Données Brutes'!D:D,A12) | I12: =COUNTIFS('📊 Données Brutes'!D:D,A12,'📊 Données Brutes'!I:I,"⚠️ Dépassement") | J12: =IF(E12>0.1,"🔴 CRITIQUE",IF(E12>0.05,"🟠 Attention",IF(E12<-0.1,"🟢 Économie","🔵 OK"))) | K12: =IF(E12>0.1,"⚡ Action requise","—")
A13: TOTAL | B13: =SUM(B5:B12) | C13: =SUM(C5:C12) | D13: =SUM(D5:D12) | E13: =IF(B13=0,0,(C13-B13)/B13)
A16: ▌ TABLE CROISÉE — TAUX DE RÉALISATION PAR DÉPARTEMENT × POSTE (annuel, % budget réalisé)
A17: Dépt \ Poste | B17: Salaires | C17: Chg Soc. | D17: Loyer | E17: Matières | F17: Informatiq. | G17: Déplacemts | H17: Formation | I17: Publicité
A18: RH | B18: =IFERROR(SUMPRODUCT(('📊 Données Brutes'!C$3:C$481=A18)*('📊 Données Brutes'!D$3:D$481="Salaires")*'📊 Données Brutes'!F$3:F$481)/SUMPRODUCT(('📊 Données Brutes'!C$3:C$481=A18)*('📊 Données Brutes'!D$3:D$481="Salaires")*'📊 Données Brutes'!E$3:E$481),0) | C18: =IFERROR(SUMPRODUCT(('📊 Données Brutes'!C$3:C$481=A18)*('📊 Données Brutes'!D$3:D$481="Charges sociales")*'📊 Données Brutes'!F$3:F$481)/SUMPRODUCT(('📊 Données Brutes'!C$3:C$481=A18)*('📊 Données Brutes'!D$3:D$481="Charges sociales")*'📊 Données Brutes'!E$3:E$481),0) | D18: =IFERROR(SUMPRODUCT(('📊 Données Brutes'!C$3:C$481=A18)*('📊 Données Brutes'!D$3:D$481="Loyer & Charges")*'📊 Données Brutes'!F$3:F$481)/SUMPRODUCT(('📊 Données Brutes'!C$3:C$481=A18)*('📊 Données Brutes'!D$3:D$481="Loyer & Charges")*'📊 Données Brutes'!E$3:E$481),0) | E18: =IFERROR(SUMPRODUCT(('📊 Données Brutes'!C$3:C$481=A18)*('📊 Données Brutes'!D$3:D$481="Matières & Fournitures")*'📊 Données Brutes'!F$3:F$481)/SUMPRODUCT(('📊 Données Brutes'!C$3:C$481=A18)*('📊 Données Brutes'!D$3:D$481="Matières & Fournitures")*'📊 Données Brutes'!E$3:E$481),0) | F18: =IFERROR(SUMPRODUCT(('📊 Données Brutes'!C$3:C$481=A18)*('📊 Données Brutes'!D$3:D$481="Informatique & Licences")*'📊 Données Brutes'!F$3:F$481)/SUMPRODUCT(('📊 Données Brutes'!C$3:C$481=A18)*('📊 Données Brutes'!D$3:D$481="Informatique & Licences")*'📊 Données Brutes'!E$3:E$481),0) | G18: =IFERROR(SUMPRODUCT(('📊 Données Brutes'!C$3:C$481=A18)*('📊 Données Brutes'!D$3:D$481="Déplacements & Missions")*'📊 Données Brutes'!F$3:F$481)/SUMPRODUCT(('📊 Données Brutes'!C$3:C$481=A18)*('📊 Données Brutes'!D$3:D$481="Déplacements & Missions")*'📊 Données Brutes'!E$3:E$481),0) | H18: =IFERROR(SUMPRODUCT(('📊 Données Brutes'!C$3:C$481=A18)*('📊 Données Brutes'!D$3:D$481="Formation")*'📊 Données Brutes'!F$3:F$481)/SUMPRODUCT(('📊 Données Brutes'!C$3:C$481=A18)*('📊 Données Brutes'!D$3:D$481="Formation")*'📊 Données Brutes'!E$3:E$481),0) | I18: =IFERROR(SUMPRODUCT(('📊 Données Brutes'!C$3:C$481=A18)*('📊 Données Brutes'!D$3:D$481="Publicité & Communication")*'📊 Données Brutes'!F$3:F$481)/SUMPRODUCT(('📊 Données Brutes'!C$3:C$481=A18)*('📊 Données Brutes'!D$3:D$481="Publicité & Communication")*'📊 Données Brutes'!E$3:E$481),0)
A19: Marketing | B19: =IFERROR(SUMPRODUCT(('📊 Données Brutes'!C$3:C$481=A19)*('📊 Données Brutes'!D$3:D$481="Salaires")*'📊 Données Brutes'!F$3:F$481)/SUMPRODUCT(('📊 Données Brutes'!C$3:C$481=A19)*('📊 Données Brutes'!D$3:D$481="Salaires")*'📊 Données Brutes'!E$3:E$481),0) | C19: =IFERROR(SUMPRODUCT(('📊 Données Brutes'!C$3:C$481=A19)*('📊 Données Brutes'!D$3:D$481="Charges sociales")*'📊 Données Brutes'!F$3:F$481)/SUMPRODUCT(('📊 Données Brutes'!C$3:C$481=A19)*('📊 Données Brutes'!D$3:D$481="Charges sociales")*'📊 Données Brutes'!E$3:E$481),0) | D19: =IFERROR(SUMPRODUCT(('📊 Données Brutes'!C$3:C$481=A19)*('📊 Données Brutes'!D$3:D$481="Loyer & Charges")*'📊 Données Brutes'!F$3:F$481)/SUMPRODUCT(('📊 Données Brutes'!C$3:C$481=A19)*('📊 Données Brutes'!D$3:D$481="Loyer & Charges")*'📊 Données Brutes'!E$3:E$481),0) | E19: =IFERROR(SUMPRODUCT(('📊 Données Brutes'!C$3:C$481=A19)*('📊 Données Brutes'!D$3:D$481="Matières & Fournitures")*'📊 Données Brutes'!F$3:F$481)/SUMPRODUCT(('📊 Données Brutes'!C$3:C$481=A19)*('📊 Données Brutes'!D$3:D$481="Matières & Fournitures")*'📊 Données Brutes'!E$3:E$481),0) | F19: =IFERROR(SUMPRODUCT(('📊 Données Brutes'!C$3:C$481=A19)*('📊 Données Brutes'!D$3:D$481="Informatique & Licences")*'📊 Données Brutes'!F$3:F$481)/SUMPRODUCT(('📊 Données Brutes'!C$3:C$481=A19)*('📊 Données Brutes'!D$3:D$481="Informatique & Licences")*'📊 Données Brutes'!E$3:E$481),0) | G19: =IFERROR(SUMPRODUCT(('📊 Données Brutes'!C$3:C$481=A19)*('📊 Données Brutes'!D$3:D$481="Déplacements & Missions")*'📊 Données Brutes'!F$3:F$481)/SUMPRODUCT(('📊 Données Brutes'!C$3:C$481=A19)*('📊 Données Brutes'!D$3:D$481="Déplacements & Missions")*'📊 Données Brutes'!E$3:E$481),0) | H19: =IFERROR(SUMPRODUCT(('📊 Données Brutes'!C$3:C$481=A19)*('📊 Données Brutes'!D$3:D$481="Formation")*'📊 Données Brutes'!F$3:F$481)/SUMPRODUCT(('📊 Données Brutes'!C$3:C$481=A19)*('📊 Données Brutes'!D$3:D$481="Formation")*'📊 Données Brutes'!E$3:E$481),0) | I19: =IFERROR(SUMPRODUCT(('📊 Données Brutes'!C$3:C$481=A19)*('📊 Données Brutes'!D$3:D$481="Publicité & Communication")*'📊 Données Brutes'!F$3:F$481)/SUMPRODUCT(('📊 Données Brutes'!C$3:C$481=A19)*('📊 Données Brutes'!D$3:D$481="Publicité & Communication")*'📊 Données Brutes'!E$3:E$481),0)
A20: Production | B20: =IFERROR(SUMPRODUCT(('📊 Données Brutes'!C$3:C$481=A20)*('📊 Données Brutes'!D$3:D$481="Salaires")*'📊 Données Brutes'!F$3:F$481)/SUMPRODUCT(('📊 Données Brutes'!C$3:C$481=A20)*('📊 Données Brutes'!D$3:D$481="Salaires")*'📊 Données Brutes'!E$3:E$481),0) | C20: =IFERROR(SUMPRODUCT(('📊 Données Brutes'!C$3:C$481=A20)*('📊 Données Brutes'!D$3:D$481="Charges sociales")*'📊 Données Brutes'!F$3:F$481)/SUMPRODUCT(('📊 Données Brutes'!C$3:C$481=A20)*('📊 Données Brutes'!D$3:D$481="Charges sociales")*'📊 Données Brutes'!E$3:E$481),0) | D20: =IFERROR(SUMPRODUCT(('📊 Données Brutes'!C$3:C$481=A20)*('📊 Données Brutes'!D$3:D$481="Loyer & Charges")*'📊 Données Brutes'!F$3:F$481)/SUMPRODUCT(('📊 Données Brutes'!C$3:C$481=A20)*('📊 Données Brutes'!D$3:D$481="Loyer & Charges")*'📊 Données Brutes'!E$3:E$481),0) | E20: =IFERROR(SUMPRODUCT(('📊 Données Brutes'!C$3:C$481=A20)*('📊 Données Brutes'!D$3:D$481="Matières & Fournitures")*'📊 Données Brutes'!F$3:F$481)/SUMPRODUCT(('📊 Données Brutes'!C$3:C$481=A20)*('📊 Données Brutes'!D$3:D$481="Matières & Fournitures")*'📊 Données Brutes'!E$3:E$481),0) | F20: =IFERROR(SUMPRODUCT(('📊 Données Brutes'!C$3:C$481=A20)*('📊 Données Brutes'!D$3:D$481="Informatique & Licences")*'📊 Données Brutes'!F$3:F$481)/SUMPRODUCT(('📊 Données Brutes'!C$3:C$481=A20)*('📊 Données Brutes'!D$3:D$481="Informatique & Licences")*'📊 Données Brutes'!E$3:E$481),0) | G20: =IFERROR(SUMPRODUCT(('📊 Données Brutes'!C$3:C$481=A20)*('📊 Données Brutes'!D$3:D$481="Déplacements & Missions")*'📊 Données Brutes'!F$3:F$481)/SUMPRODUCT(('📊 Données Brutes'!C$3:C$481=A20)*('📊 Données Brutes'!D$3:D$481="Déplacements & Missions")*'📊 Données Brutes'!E$3:E$481),0) | H20: =IFERROR(SUMPRODUCT(('📊 Données Brutes'!C$3:C$481=A20)*('📊 Données Brutes'!D$3:D$481="Formation")*'📊 Données Brutes'!F$3:F$481)/SUMPRODUCT(('📊 Données Brutes'!C$3:C$481=A20)*('📊 Données Brutes'!D$3:D$481="Formation")*'📊 Données Brutes'!E$3:E$481),0) | I20: =IFERROR(SUMPRODUCT(('📊 Données Brutes'!C$3:C$481=A20)*('📊 Données Brutes'!D$3:D$481="Publicité & Communication")*'📊 Données Brutes'!F$3:F$481)/SUMPRODUCT(('📊 Données Brutes'!C$3:C$481=A20)*('📊 Données Brutes'!D$3:D$481="Publicité & Communication")*'📊 Données Brutes'!E$3:E$481),0)
A21: IT | B21: =IFERROR(SUMPRODUCT(('📊 Données Brutes'!C$3:C$481=A21)*('📊 Données Brutes'!D$3:D$481="Salaires")*'📊 Données Brutes'!F$3:F$481)/SUMPRODUCT(('📊 Données Brutes'!C$3:C$481=A21)*('📊 Données Brutes'!D$3:D$481="Salaires")*'📊 Données Brutes'!E$3:E$481),0) | C21: =IFERROR(SUMPRODUCT(('📊 Données Brutes'!C$3:C$481=A21)*('📊 Données Brutes'!D$3:D$481="Charges sociales")*'📊 Données Brutes'!F$3:F$481)/SUMPRODUCT(('📊 Données Brutes'!C$3:C$481=A21)*('📊 Données Brutes'!D$3:D$481="Charges sociales")*'📊 Données Brutes'!E$3:E$481),0) | D21: =IFERROR(SUMPRODUCT(('📊 Données Brutes'!C$3:C$481=A21)*('📊 Données Brutes'!D$3:D$481="Loyer & Charges")*'📊 Données Brutes'!F$3:F$481)/SUMPRODUCT(('📊 Données Brutes'!C$3:C$481=A21)*('📊 Données Brutes'!D$3:D$481="Loyer & Charges")*'📊 Données Brutes'!E$3:E$481),0) | E21: =IFERROR(SUMPRODUCT(('📊 Données Brutes'!C$3:C$481=A21)*('📊 Données Brutes'!D$3:D$481="Matières & Fournitures")*'📊 Données Brutes'!F$3:F$481)/SUMPRODUCT(('📊 Données Brutes'!C$3:C$481=A21)*('📊 Données Brutes'!D$3:D$481="Matières & Fournitures")*'📊 Données Brutes'!E$3:E$481),0) | F21: =IFERROR(SUMPRODUCT(('📊 Données Brutes'!C$3:C$481=A21)*('📊 Données Brutes'!D$3:D$481="Informatique & Licences")*'📊 Données Brutes'!F$3:F$481)/SUMPRODUCT(('📊 Données Brutes'!C$3:C$481=A21)*('📊 Données Brutes'!D$3:D$481="Informatique & Licences")*'📊 Données Brutes'!E$3:E$481),0) | G21: =IFERROR(SUMPRODUCT(('📊 Données Brutes'!C$3:C$481=A21)*('📊 Données Brutes'!D$3:D$481="Déplacements & Missions")*'📊 Données Brutes'!F$3:F$481)/SUMPRODUCT(('📊 Données Brutes'!C$3:C$481=A21)*('📊 Données Brutes'!D$3:D$481="Déplacements & Missions")*'📊 Données Brutes'!E$3:E$481),0) | H21: =IFERROR(SUMPRODUCT(('📊 Données Brutes'!C$3:C$481=A21)*('📊 Données Brutes'!D$3:D$481="Formation")*'📊 Données Brutes'!F$3:F$481)/SUMPRODUCT(('📊 Données Brutes'!C$3:C$481=A21)*('📊 Données Brutes'!D$3:D$481="Formation")*'📊 Données Brutes'!E$3:E$481),0) | I21: =IFERROR(SUMPRODUCT(('📊 Données Brutes'!C$3:C$481=A21)*('📊 Données Brutes'!D$3:D$481="Publicité & Communication")*'📊 Données Brutes'!F$3:F$481)/SUMPRODUCT(('📊 Données Brutes'!C$3:C$481=A21)*('📊 Données Brutes'!D$3:D$481="Publicité & Communication")*'📊 Données Brutes'!E$3:E$481),0)
A22: Administration | B22: =IFERROR(SUMPRODUCT(('📊 Données Brutes'!C$3:C$481=A22)*('📊 Données Brutes'!D$3:D$481="Salaires")*'📊 Données Brutes'!F$3:F$481)/SUMPRODUCT(('📊 Données Brutes'!C$3:C$481=A22)*('📊 Données Brutes'!D$3:D$481="Salaires")*'📊 Données Brutes'!E$3:E$481),0) | C22: =IFERROR(SUMPRODUCT(('📊 Données Brutes'!C$3:C$481=A22)*('📊 Données Brutes'!D$3:D$481="Charges sociales")*'📊 Données Brutes'!F$3:F$481)/SUMPRODUCT(('📊 Données Brutes'!C$3:C$481=A22)*('📊 Données Brutes'!D$3:D$481="Charges sociales")*'📊 Données Brutes'!E$3:E$481),0) | D22: =IFERROR(SUMPRODUCT(('📊 Données Brutes'!C$3:C$481=A22)*('📊 Données Brutes'!D$3:D$481="Loyer & Charges")*'📊 Données Brutes'!F$3:F$481)/SUMPRODUCT(('📊 Données Brutes'!C$3:C$481=A22)*('📊 Données Brutes'!D$3:D$481="Loyer & Charges")*'📊 Données Brutes'!E$3:E$481),0) | E22: =IFERROR(SUMPRODUCT(('📊 Données Brutes'!C$3:C$481=A22)*('📊 Données Brutes'!D$3:D$481="Matières & Fournitures")*'📊 Données Brutes'!F$3:F$481)/SUMPRODUCT(('📊 Données Brutes'!C$3:C$481=A22)*('📊 Données Brutes'!D$3:D$481="Matières & Fournitures")*'📊 Données Brutes'!E$3:E$481),0) | F22: =IFERROR(SUMPRODUCT(('📊 Données Brutes'!C$3:C$481=A22)*('📊 Données Brutes'!D$3:D$481="Informatique & Licences")*'📊 Données Brutes'!F$3:F$481)/SUMPRODUCT(('📊 Données Brutes'!C$3:C$481=A22)*('📊 Données Brutes'!D$3:D$481="Informatique & Licences")*'📊 Données Brutes'!E$3:E$481),0) | G22: =IFERROR(SUMPRODUCT(('📊 Données Brutes'!C$3:C$481=A22)*('📊 Données Brutes'!D$3:D$481="Déplacements & Missions")*'📊 Données Brutes'!F$3:F$481)/SUMPRODUCT(('📊 Données Brutes'!C$3:C$481=A22)*('📊 Données Brutes'!D$3:D$481="Déplacements & Missions")*'📊 Données Brutes'!E$3:E$481),0) | H22: =IFERROR(SUMPRODUCT(('📊 Données Brutes'!C$3:C$481=A22)*('📊 Données Brutes'!D$3:D$481="Formation")*'📊 Données Brutes'!F$3:F$481)/SUMPRODUCT(('📊 Données Brutes'!C$3:C$481=A22)*('📊 Données Brutes'!D$3:D$481="Formation")*'📊 Données Brutes'!E$3:E$481),0) | I22: =IFERROR(SUMPRODUCT(('📊 Données Brutes'!C$3:C$481=A22)*('📊 Données Brutes'!D$3:D$481="Publicité & Communication")*'📊 Données Brutes'!F$3:F$481)/SUMPRODUCT(('📊 Données Brutes'!C$3:C$481=A22)*('📊 Données Brutes'!D$3:D$481="Publicité & Communication")*'📊 Données Brutes'!E$3:E$481),0)
